<?xml version="1.0" encoding="utf-8"?>
<!-- =================================================================================== -->
<!-- |    This document is a hand-crafted representation of the MEAM 2110 Furuta       | -->
<!-- |    pendulum.                                                                    | -->
<!-- =================================================================================== -->
<robot name="furuta_pendulum">
  <link name="inertial_frame">
   <!-- Need an empty object to make a joint with the one link -->
    <inertial>
      <mass value="0"/>
      <origin xyz="0 0 0" rpy="0 0 0"/>
      <inertia ixx="0" ixy="0" ixz="0" iyy="0" iyz="0" izz="0"/>
    </inertial>
  </link>

  <link name="body_B">
  <!-- Single character link names aren't properly parsed by ParseVisual.m -->
    <inertial>
      <!-- mass=1 -->
      <mass value="1."/>
      
      <!-- r_Bo_Bcm=[0.5, 0, 0.], R_B_V = eye(3) -->
      <origin xyz="0.5 0 0" rpy="0 0 0"/>

      <!-- I_B_Bcm = zeros(3) -->
      <inertia ixx="0" ixy="0" ixz="0" iyy="0" iyz="0" izz="0"/>
    </inertial>

    <visual>
      <!-- r_Bo_Vo=[0.5, 0, 0.], R_B_V = eye(3) -->
      <origin xyz="0.5 0 0" rpy="0 0 0"/>

      <geometry>
        <!-- sides=[1, 0.1, 0.1] -->
        <box size="1 0.1 0.1"/>
      </geometry>
    </visual>
  </link>

  <link name="body_C">
    <inertial>
      <!-- mass=0.5 -->
      <mass value="0.5"/>
      
      <!-- r_Co_Ccm=[0.25, 0, 0], R_C_V = eye(3) -->
      <origin xyz="0.25 0 0" rpy="0 0 0"/>

      <!-- I_C_Ccm = zeros(3) -->
      <inertia ixx="0" ixy="0" ixz="0" iyy="0" iyz="0" izz="0"/>
    </inertial>

    <visual>
      <!-- r_Co_Vo=[0.25, 0, 0], R_C_V = eye(3) -->
      <origin xyz="0.25 0 0" rpy="0 0 0"/>

      <geometry>
        <!-- sides=[0.5, 0.05, 0.1] -->
        <box size="0.5 0.05 0.1"/>
      </geometry>
    </visual>
  </link>

  <link name="body_D">
    <inertial>
      <!-- mass=0.5 -->
      <mass value="0.5"/>
      
      <!-- r_Co_Ccm=[0.25, 0, 0], R_C_V = eye(3) -->
      <origin xyz="0.25 0 0" rpy="0 0 0"/>

      <!-- I_C_Ccm = zeros(3) -->
      <inertia ixx="0" ixy="0" ixz="0" iyy="0" iyz="0" izz="0"/>
    </inertial>

    <visual>
      <!-- r_Co_Vo=[0.25, 0, 0], R_C_V = eye(3) -->
      <origin xyz="0.25 0 0" rpy="0 0 0"/>

      <geometry>
        <!-- sides=[0.5, 0.05, 0.1] -->
        <box size="0.5 0.05 0.1"/>
      </geometry>
    </visual>
  </link>

  <link name="body_E">
    <inertial>
      <!-- mass=0.1 -->
      <mass value="0.1"/>
      
      <!-- r_Do_Dcm=[0, 0, 0], R_C_V = eye(3) -->
      <origin xyz="0 0 0" rpy="0 0 0"/>

      <!-- I_D_Dcm = zeros(3) -->
      <inertia ixx="0" ixy="0" ixz="0" iyy="0" iyz="0" izz="0"/>
    </inertial>

    <!-- No visual for body E -->

  </link>

  <joint name="joint_1" type="revolute">
    <!-- r_Po_J1o=[0,0,0], R_P_J1=eye(3) -->
    <origin xyz="0 0 0" rpy="0 0 0"/>
    
    <!-- joint_axis=[0, 0, 1] -->
    <axis xyz="0 0 1"/>

    <parent link="inertial_frame"/>
    <child link="body_B"/>

    <!-- Necessary tags but values don't matter -->
    <limit effort="0" velocity="0"/>
  </joint>

  <joint name="joint_2" type="revolute">
    <!-- r_Bo_J2o=[1,0,0], R_B_J2=eye(3) -->
    <origin xyz="1 0 0" rpy="0 0 0"/>
    
    <!-- joint_axis=[0, 1, 0] -->
    <axis xyz="0 1 0"/>

    <parent link="body_B"/>
    <child link="body_C"/>

    <!-- Necessary tags but values don't matter -->
    <limit effort="0" velocity="0"/>
  </joint>

  <joint name="joint_3" type="revolute">
    <!-- r_Bo_J2o=[1,0,0], R_B_J2=eye(3) -->
    <origin xyz="0.5 0 0" rpy="0 0 0"/>
    
    <!-- joint_axis=[0, 1, 0] -->
    <axis xyz="0 1 0"/>

    <parent link="body_C"/>
    <child link="body_D"/>

    <!-- Necessary tags but values don't matter -->
    <limit effort="0" velocity="0"/>
  </joint>

  <joint name="joint_4" type="fixed">
    <!-- r_Co_J3o=[0,0,0], R_C_J3=eye(3) -->
    <origin xyz="0 0 0" rpy="0 0 0"/>

    <parent link="body_D"/>
    <child link="body_E"/>
  </joint>
</robot>
