<?xml version="1.0" encoding="utf-8"?>
<!-- =================================================================================== -->
<!-- |    This document is a hand-crafted representation of the MEAM 2110 pendulum.    | -->
<!-- =================================================================================== -->
<robot name="chaotic_pendulum">
  <link name="inertial_N"/>

  <link name="body_A">
    <inertial>
      <!-- mass=1 -->
      <mass value=".5"/>
      
      <!-- r_Bo_Bcm=[0, 0, -0.5], R_B_V = eye(3) -->
      <origin xyz="0 0 -0.5" rpy="0 0 0"/>

      <!-- I_B_Bcm = zeros(3) -->
      <inertia ixx="0" ixy="0" ixz="0" iyy="0" iyz="0" izz="0"/>
    </inertial>

    <visual>
      <!-- r_Bo_Vo=[0, 0, -0.5], R_B_V = eye(3) -->
      <origin xyz="0 0 -0.5" rpy="0 0 0"/>

      <geometry>
        <!-- sides=[0.1, 0.1, 1] -->
        <box size="0.1 0.1 1"/>
      </geometry>
    </visual>
  </link>

  <link name="body_B">
    <inertial>
      <!-- mass=1 -->
      <mass value="2."/>
      
      <!-- r_Bo_Bcm=[0, 0, -0.25], R_B_V = eye(3) -->
      <origin xyz="0 0 -0.25" rpy="0 0 0"/>

      <!-- I_B_Bcm = zeros(3) -->
      <inertia ixx=".1" ixy="0" ixz="0" iyy=".1" iyz="0" izz=".1  "/>
    </inertial>

    <visual>
      <!-- r_Bo_Vo=[0, 0, -0.25], R_B_V = eye(3) -->
      <origin xyz="0 0 -0.25" rpy="0 0 0"/>

      <geometry>
        <!-- sides=[0.05, 0.5, .5] -->
        <box size="0.05 0.5 .5"/>
      </geometry>
    </visual>
  </link>

  <joint name="pendulum_hinge" type="revolute">
    <!-- r_Po_Jo=[0,0,0], R_P_J=eye(3) -->
    <origin xyz="0 0 0" rpy="0 0 0"/>
    
    <!-- joint_axis=[1, 0, 0] -->
    <axis xyz="1 0 0"/>

    <parent link="inertial_N"/>
    <child link="body_A"/>

    <!-- Necessary tags but values don't matter -->
    <limit effort="0" velocity="0"/>
  </joint>

  <joint name="boot_hinge" type="revolute">
    <!-- r_Po_Jo=[0,0,-1], R_P_J=eye(3) -->
    <origin xyz="0 0 -1" rpy="0 0 0"/>
    
    <!-- joint_axis=[0, 0, 1] -->
    <axis xyz="0 0 1"/>

    <parent link="body_A"/>
    <child link="body_B"/>

    <!-- Necessary tags but values don't matter -->
    <limit effort="0" velocity="0"/>
  </joint>
</robot>
