<?xml version="1.0" encoding="utf-8"?>
<!-- =================================================================================== -->
<!-- |    This document is a hand-crafted representation of the MEAM 2110 double pendulum.    | -->
<!-- =================================================================================== -->
<robot name="pendulum">
  <link name="inertial_N"/>

  <link name="body_B">
  <!-- Single character link names aren't properly parsed by ParseVisual.m -->
    <inertial>
      <!-- mass=1 -->
      <mass value="1."/>

      <!-- r_Bo_Bcm=[0, 0, 0.5], R_B_V = eye(3) -->
      <origin xyz="0 0 -0.5" rpy="0 0 0"/>

      <!-- I_B_Bcm = zeros(3) -->
      <inertia ixx="0" ixy="0" ixz="0" iyy="0" iyz="0" izz="0"/>
    </inertial>

    <visual>
      <!-- r_Bo_Vo=[0, 0, 0.5], R_B_V = eye(3) -->
      <origin xyz="0 0 -0.5" rpy="0 0 0"/>

      <geometry>
        <!-- sides=[0.1, 0.2, 1] -->
        <box size="0.1 0.2 1"/>
      </geometry>
    </visual>
  </link>

  <link name="body_C">
  <!-- Single character link names aren't properly parsed by ParseVisual.m -->
    <inertial>
      <!-- mass=1 -->
      <mass value="1."/>

      <!-- r_Bo_Bcm=[0, 0, 0.5], R_B_V = eye(3) -->
      <origin xyz="0 0 -0.5" rpy="0 0 0"/>

      <!-- I_B_Bcm = zeros(3) -->
      <inertia ixx="0" ixy="0" ixz="0" iyy="0" iyz="0" izz="0"/>
    </inertial>

    <visual>
      <!-- r_Bo_Vo=[0, 0, 0.5], R_B_V = eye(3) -->
      <origin xyz="0 0 -0.5" rpy="0 0 0"/>

      <geometry>
        <!-- sides=[0.1, 0.2, 1] -->
        <box size="0.1 0.2 1"/>
      </geometry>
    </visual>
  </link>


  <joint name="pendulum_hinge" type="revolute">
    <!-- r_Po_Jo=[0,0,0], R_P_J=eye(3) -->
    <origin xyz="0 0 0" rpy="0 0 0"/>
    
    <!-- joint_axis=[0, 1, 0] -->
    <axis xyz="0 1 0"/>

    <parent link="inertial_N"/>
    <child link="body_B"/>

    <!-- Necessary tags but values don't matter -->
    <limit effort="0" velocity="0"/>
  </joint>

 <joint name="pendulum_hinge1" type="revolute">
    <!-- r_Po_Jo=[0,0,0], R_P_J=eye(3) -->
    <origin xyz="0 0 -1" rpy="0 0 0"/>
    
    <!-- joint_axis=[0, 1, 0] -->
    <axis xyz="0 1 0"/>

    <parent link="body_B"/>
    <child link="body_C"/>

    <!-- Necessary tags but values don't matter -->
    <limit effort="0" velocity="0"/>
  </joint>



</robot>
