<?xml version="1.0" encoding="utf-8"?>
<!-- =================================================================================== -->
<!-- |    This document is a hand-crafted representation of a singular floating base   | -->
<!-- |    of cube shape with decorative "thrusters" for MEAM 2110.                     | -->
<!-- =================================================================================== -->
<robot name="spacecraft">
  <link name="inertial_frame">
   <!-- Need an empty object to make a joint with the one link -->
    <inertial>
      <mass value="0"/>
      <origin xyz="0 0 0" rpy="0 0 0"/>
      <inertia ixx="0" ixy="0" ixz="0" iyy="0" iyz="0" izz="0"/>
    </inertial>
  </link>

  <link name="frame_A">
  <!-- Single character link names aren't properly parsed by ParseVisual.m -->
   <!-- Need an empty object to get to 6-DOF joint to racket handle (F) -->
  </link>

  <link name="frame_B">
   <!-- Need an empty object to get to 6-DOF joint to racket handle (F) -->
  </link>

  <link name="frame_C">
   <!-- Need an empty object to get to 6-DOF joint to racket handle (F) -->
  </link>

  <link name="frame_D">
   <!-- Need an empty object to get to 6-DOF joint to racket handle (F) -->
  </link>

  <link name="frame_E">
   <!-- Need an empty object to get to 6-DOF joint to racket handle (F) -->
  </link>

  <link name="arm_1">
    <visual>
      <!-- r_Co_Vo=[-0.25, 0, 0], R_C_V = eye(3) -->
      <origin xyz="-0.25 0 0" rpy="0 0 0"/>

      <geometry>
        <!-- sides=[0.25 0.0417 0.0417] -->
        <box size="0.25 0.0417 0.0417"/>
      </geometry>
    </visual>
  </link>

  <link name="arm_2">
    <visual>
      <origin xyz="0 -0.25 0" rpy="0 0 0"/>

      <geometry>
        <box size="0.0417 0.25 0.0417"/>
      </geometry>
    </visual>
  </link>

  <link name="arm_3">
    <visual>
      <origin xyz="0 0 -0.25" rpy="0 0 0"/>

      <geometry>
        <box size="0.0417 0.0417 0.25"/>
      </geometry>
    </visual>
  </link>

  <link name="arm_4">
    <visual>
      <origin xyz="0.25 0 0" rpy="0 0 0"/>

      <geometry>
        <box size="0.25 0.0417 0.0417"/>
      </geometry>
    </visual>
  </link>

  <link name="arm_5">
    <visual>
      <origin xyz="0 0.25 0" rpy="0 0 0"/>

      <geometry>
        <box size="0.0417 0.25 0.0417"/>
      </geometry>
    </visual>
  </link>

  <link name="arm_6">
    <visual>
      <origin xyz="0 0 0.25" rpy="0 0 0"/>

      <geometry>
        <box size="0.0417 0.0417 0.25"/>
      </geometry>
    </visual>
  </link>

  <link name="thruster_1">
    <visual>
      <origin xyz="-0.4167 0 0" rpy="0 0 0"/>

      <geometry>
        <box size="0.0833 0.1667 0.0833"/>
      </geometry>
      
      <material name="red">
        <color rgba="1.0 0.5 0.5 1.0" />
      </material>
    </visual>
  </link>

  <link name="thruster_2">
    <visual>
      <origin xyz="0 -0.4167 0" rpy="0 0 0"/>

      <geometry>
        <box size="0.0833 0.0833 0.1667"/>
      </geometry>
      
      <material name="green">
        <color rgba="0.5 1.0 0.5 1.0" />
      </material>
    </visual>
  </link>

  <link name="thruster_3">
    <visual>
      <origin xyz="0 0 -0.4167" rpy="0 0 0"/>

      <geometry>
        <box size="0.1667 0.0833 0.0833"/>
      </geometry>
      
      <material name="blue">
        <color rgba="0.5 0.5 1.0 1.0" />
      </material>
    </visual>
  </link>

  <link name="thruster_4">
    <visual>
      <origin xyz="0.4167 0 0" rpy="0 0 0"/>

      <geometry>
        <box size="0.0833 0.1667 0.0833"/>
      </geometry>
      
      <material name="red">
        <color rgba="1.0 0.5 0.5 1.0" />
      </material>
    </visual>
  </link>

  <link name="thruster_5">
    <visual>
      <origin xyz="0 0.4167 0" rpy="0 0 0"/>

      <geometry>
        <box size="0.0833 0.0833 0.1667"/>
      </geometry>
      
      <material name="green">
        <color rgba="0.5 1.0 0.5 1.0" />
      </material>
    </visual>
  </link>

  <link name="thruster_6">
    <visual>
      <origin xyz="0 0 0.4167" rpy="0 0 0"/>

      <geometry>
        <box size="0.1667 0.0833 0.0833"/>
      </geometry>
      
      <material name="blue">
        <color rgba="0.5 0.5 1.0 1.0" />
      </material>
    </visual>
  </link>

  <link name="body_F">
    <inertial>
      <!-- mass=0.5 -->
      <mass value="0.5"/>
      
      <!-- r_Co_Ccm=[0, 0, 0], R_C_V = eye(3) -->
      <origin xyz="0 0 0" rpy="0 0 0"/>

      <!-- I_C_Ccm = zeros(3) -->
      <inertia ixx="0.052" ixy="0" ixz="0" iyy="0.052" iyz="0" izz="0.052"/>
    </inertial>

    <visual>
      <!-- r_Co_Vo=[0, 0, 0], R_C_V = eye(3) -->
      <origin xyz="0 0 0" rpy="0 0 0"/>

      <geometry>
        <!-- sides=[0.25 0.25 0.25] -->
        <box size="0.25 0.25 0.25"/>
      </geometry>
    </visual>
  </link>


  <joint name="trans_x" type="prismatic">
    <origin xyz="0 0 0" rpy="0 0 0"/>
    <limit upper="1000" lower="-1000" effort="10000" velocity="10000"/>
    <parent link="inertial_frame" />
    <child link="frame_A" />
    <axis xyz="1 0 0"/>
  </joint>
  <joint name="trans_y" type="prismatic">
    <origin xyz="0 0 0" rpy="0 0 0"/>
    <limit upper="1000" lower="-1000" effort="10000" velocity="10000"/>
    <parent link="frame_A" />
    <child link="frame_B" />
    <axis xyz="0 1 0"/>
  </joint>
  <joint name="trans_z" type="prismatic">
    <origin xyz="0 0 0" rpy="0 0 0"/>
    <limit upper="1000" lower="-1000" effort="10000" velocity="10000"/>
    <parent link="frame_B" />
    <child link="frame_C" />
    <axis xyz="0 0 1"/>
  </joint>
  <joint name="rot_x" type="continuous">
    <origin xyz="0 0 0" rpy="0 0 0"/>
    <parent link="frame_C" />
    <child link="frame_D" />
    <axis xyz="1 0 0"/>
  </joint>
  <joint name="rot_y" type="continuous">
    <origin xyz="0 0 0" rpy="0 0 0"/>
    <parent link="frame_D" />
    <child link="frame_E" />
      <axis xyz="0 1 0"/>
  </joint>
  <joint name="rot_z" type="continuous">
    <origin xyz="0 0 0" rpy="0 0 0"/>
    <parent link="frame_E" />
    <child link="body_F" />
      <axis xyz="0 0 1"/>
  </joint>


  <joint name="arm_1_weld" type="fixed">
    <origin xyz="0 0 0" rpy="0 0 0"/>
    <parent link="body_F"/>
    <child link="arm_1"/>
  </joint>
  <joint name="arm_2_weld" type="fixed">
    <origin xyz="0 0 0" rpy="0 0 0"/>
    <parent link="body_F"/>
    <child link="arm_2"/>
  </joint>
  <joint name="arm_3_weld" type="fixed">
    <origin xyz="0 0 0" rpy="0 0 0"/>
    <parent link="body_F"/>
    <child link="arm_3"/>
  </joint>
  <joint name="arm_4_weld" type="fixed">
    <origin xyz="0 0 0" rpy="0 0 0"/>
    <parent link="body_F"/>
    <child link="arm_4"/>
  </joint>
  <joint name="arm_5_weld" type="fixed">
    <origin xyz="0 0 0" rpy="0 0 0"/>
    <parent link="body_F"/>
    <child link="arm_5"/>
  </joint>
  <joint name="arm_6_weld" type="fixed">
    <origin xyz="0 0 0" rpy="0 0 0"/>
    <parent link="body_F"/>
    <child link="arm_6"/>
  </joint>
  <joint name="thruster_1_weld" type="fixed">
    <origin xyz="0 0 0" rpy="0 0 0"/>
    <parent link="body_F"/>
    <child link="thruster_1"/>
  </joint>
  <joint name="thruster_2_weld" type="fixed">
    <origin xyz="0 0 0" rpy="0 0 0"/>
    <parent link="body_F"/>
    <child link="thruster_2"/>
  </joint>
  <joint name="thruster_3_weld" type="fixed">
    <origin xyz="0 0 0" rpy="0 0 0"/>
    <parent link="body_F"/>
    <child link="thruster_3"/>
  </joint>
  <joint name="thruster_4_weld" type="fixed">
    <origin xyz="0 0 0" rpy="0 0 0"/>
    <parent link="body_F"/>
    <child link="thruster_4"/>
  </joint>
  <joint name="thruster_5_weld" type="fixed">
    <origin xyz="0 0 0" rpy="0 0 0"/>
    <parent link="body_F"/>
    <child link="thruster_5"/>
  </joint>
  <joint name="thruster_6_weld" type="fixed">
    <origin xyz="0 0 0" rpy="0 0 0"/>
    <parent link="body_F"/>
    <child link="thruster_6"/>
  </joint>
</robot>
