<?xml version="1.0" encoding="utf-8"?>
<!-- =================================================================================== -->
<!-- |    This document is a hand-crafted representation of the MEAM 2110 tennis       | -->
<!-- |    racket.                                                                      | -->
<!-- =================================================================================== -->
<robot name="tennis_racket">
  <link name="inertial_frame">
   <!-- Need an empty object to make a joint with the one link -->
    <inertial>
      <mass value="0"/>
      <origin xyz="0 0 0" rpy="0 0 0"/>
      <inertia ixx="0" ixy="0" ixz="0" iyy="0" iyz="0" izz="0"/>
    </inertial>
  </link>

  <link name="body_A">
  <!-- Single character link names aren't properly parsed by ParseVisual.m -->
   <!-- Need an empty object to get to 3-DOF joint to racket handle (C) -->
    <inertial>
      <mass value="0"/>
      <origin xyz="0 0 0" rpy="0 0 0"/>
      <inertia ixx="0" ixy="0" ixz="0" iyy="0" iyz="0" izz="0"/>
    </inertial>
  </link>

  <link name="body_B">
   <!-- Need an empty object to get to 3-DOF joint to racket handle (C) -->
    <inertial>
      <mass value="0"/>
      <origin xyz="0 0 0" rpy="0 0 0"/>
      <inertia ixx="0" ixy="0" ixz="0" iyy="0" iyz="0" izz="0"/>
    </inertial>
  </link>

  <link name="body_C">
    <inertial>
      <!-- mass=3.5 -->
      <mass value="3.5"/>
      
      <!-- r_Co_Ccm=[0, 0, 0.8571], R_C_V = eye(3) -->
      <origin xyz="0 0 0" rpy="0 0 0"/>

      <!-- I_C_Ccm = diag(16.7653, 5.2453, 12.52) -->
      <inertia ixx="16.7653" ixy="0" ixz="0" iyy="5.2453" iyz="0" izz="12.52"/>
    </inertial>

    <visual>
      <!-- r_Co_Vo=[0, 0, -0.8571], R_C_V = eye(3) -->
      <origin xyz="0 0 -0.8571" rpy="0 0 0"/>

      <geometry>
        <!-- sides=[0.2 0.2 2] -->
        <box size="0.2 0.2 2"/>
      </geometry>
    </visual>
  </link>

  <link name="body_D">
    <inertial>
      <!-- mass=0 -->
      <mass value="0"/>
      
      <!-- r_Co_Ccm=[0, 0, 0], R_C_V = eye(3) -->
      <origin xyz="0 0 0" rpy="0 0 0"/>

      <!-- I_C_Ccm = zeros(3) -->
      <inertia ixx="0" ixy="0" ixz="0" iyy="0" iyz="0" izz="0"/>
    </inertial>

    <visual>
      <!-- r_Co_Vo=[0, 0, 0], R_C_V = eye(3) -->
      <origin xyz="0 0 0" rpy="0 0 0"/>

      <geometry>
        <!-- sides=[0.4 2 0.4] -->
        <box size="0.4 2 0.4"/>
      </geometry>
    </visual>
  </link>

  <joint name="joint_roll" type="revolute">
    <!-- r_Po_Jo=[0,0,0], R_P_J=eye(3) -->
    <origin xyz="0 0 0" rpy="0 0 0"/>
    
    <!-- joint_axis=[1, 0, 0] -->
    <axis xyz="1 0 0"/>

    <parent link="inertial_frame"/>
    <child link="body_A"/>

    <!-- Necessary tags but values don't matter -->
    <limit effort="0" velocity="0"/>
  </joint>

  <joint name="joint_pitch" type="revolute">
    <!-- r_Po_Jo=[0,0,0], R_P_J=eye(3) -->
    <origin xyz="0 0 0" rpy="0 0 0"/>
    
    <!-- joint_axis=[0, 1, 0] -->
    <axis xyz="0 1 0"/>

    <parent link="body_A"/>
    <child link="body_B"/>

    <!-- Necessary tags but values don't matter -->
    <limit effort="0" velocity="0"/>
  </joint>

  <joint name="joint_yaw" type="revolute">
    <!-- r_Po_Jo=[0,0,0], R_P_J=eye(3) -->
    <origin xyz="0 0 0" rpy="0 0 0"/>
    
    <!-- joint_axis=[0, 0, 1] -->
    <axis xyz="0 0 1"/>

    <parent link="body_B"/>
    <child link="body_C"/>

    <!-- Necessary tags but values don't matter -->
    <limit effort="0" velocity="0"/>
  </joint>

  <joint name="joint_weld" type="fixed">
    <!-- r_Po_Jo=[0,0,0.1429], R_P_J=eye(3) -->
    <origin xyz="0 0 0.1429" rpy="0 0 0"/>

    <parent link="body_C"/>
    <child link="body_D"/>
  </joint>
</robot>
